<?xml version="1.0" ?>
<!-- =================================================================================== -->
<!-- |    This document was autogenerated by xacro from csda10f_precision_model.xacro | -->
<!-- |    EDITING THIS FILE BY HAND IS NOT RECOMMENDED                                 | -->
<!-- =================================================================================== -->
<robot name="csda10f_precision_model">
  <material name="silver">
    <color rgba="0.700 0.700 0.700 1.000"/>
  </material>
  <transmission name="A1_tran">
    <type>transmission_interface/SimpleTransmission</type>
    <joint name="A1">
      <hardwareInterface>hardware_interface/EffortJointInterface</hardwareInterface>
    </joint>
    <actuator name="A1_actr">
      <hardwareInterface>hardware_interface/EffortJointInterface</hardwareInterface>
      <mechanicalReduction>1</mechanicalReduction>
    </actuator>
  </transmission>
  <transmission name="S1_tran">
    <type>transmission_interface/SimpleTransmission</type>
    <joint name="S1">
      <hardwareInterface>hardware_interface/EffortJointInterface</hardwareInterface>
    </joint>
    <actuator name="S1_actr">
      <hardwareInterface>hardware_interface/EffortJointInterface</hardwareInterface>
      <mechanicalReduction>1</mechanicalReduction>
    </actuator>
  </transmission>
  <transmission name="L1_tran">
    <type>transmission_interface/SimpleTransmission</type>
    <joint name="L1">
      <hardwareInterface>hardware_interface/EffortJointInterface</hardwareInterface>
    </joint>
    <actuator name="L1_actr">
      <hardwareInterface>hardware_interface/EffortJointInterface</hardwareInterface>
      <mechanicalReduction>1</mechanicalReduction>
    </actuator>
  </transmission>
  <transmission name="E1_tran">
    <type>transmission_interface/SimpleTransmission</type>
    <joint name="E1">
      <hardwareInterface>hardware_interface/EffortJointInterface</hardwareInterface>
    </joint>
    <actuator name="E1_actr">
      <hardwareInterface>hardware_interface/EffortJointInterface</hardwareInterface>
      <mechanicalReduction>1</mechanicalReduction>
    </actuator>
  </transmission>
  <transmission name="U1_tran">
    <type>transmission_interface/SimpleTransmission</type>
    <joint name="U1">
      <hardwareInterface>hardware_interface/EffortJointInterface</hardwareInterface>
    </joint>
    <actuator name="U1_actr">
      <hardwareInterface>hardware_interface/EffortJointInterface</hardwareInterface>
      <mechanicalReduction>1</mechanicalReduction>
    </actuator>
  </transmission>
  <transmission name="R1_tran">
    <type>transmission_interface/SimpleTransmission</type>
    <joint name="R1">
      <hardwareInterface>hardware_interface/EffortJointInterface</hardwareInterface>
    </joint>
    <actuator name="R1_actr">
      <hardwareInterface>hardware_interface/EffortJointInterface</hardwareInterface>
      <mechanicalReduction>1</mechanicalReduction>
    </actuator>
  </transmission>
  <transmission name="B1_tran">
    <type>transmission_interface/SimpleTransmission</type>
    <joint name="B1">
      <hardwareInterface>hardware_interface/EffortJointInterface</hardwareInterface>
    </joint>
    <actuator name="B1_actr">
      <hardwareInterface>hardware_interface/EffortJointInterface</hardwareInterface>
      <mechanicalReduction>1</mechanicalReduction>
    </actuator>
  </transmission>
  <transmission name="T1_tran">
    <type>transmission_interface/SimpleTransmission</type>
    <joint name="T1">
      <hardwareInterface>hardware_interface/EffortJointInterface</hardwareInterface>
    </joint>
    <actuator name="T1_actr">
      <hardwareInterface>hardware_interface/EffortJointInterface</hardwareInterface>
      <mechanicalReduction>1</mechanicalReduction>
    </actuator>
  </transmission>
  <transmission name="S2_tran">
    <type>transmission_interface/SimpleTransmission</type>
    <joint name="S2">
      <hardwareInterface>hardware_interface/EffortJointInterface</hardwareInterface>
    </joint>
    <actuator name="S2_actr">
      <hardwareInterface>hardware_interface/EffortJointInterface</hardwareInterface>
      <mechanicalReduction>1</mechanicalReduction>
    </actuator>
  </transmission>
  <transmission name="L2_tran">
    <type>transmission_interface/SimpleTransmission</type>
    <joint name="L2">
      <hardwareInterface>hardware_interface/EffortJointInterface</hardwareInterface>
    </joint>
    <actuator name="L2_actr">
      <hardwareInterface>hardware_interface/EffortJointInterface</hardwareInterface>
      <mechanicalReduction>1</mechanicalReduction>
    </actuator>
  </transmission>
  <transmission name="E2_tran">
    <type>transmission_interface/SimpleTransmission</type>
    <joint name="E2">
      <hardwareInterface>hardware_interface/EffortJointInterface</hardwareInterface>
    </joint>
    <actuator name="E2_actr">
      <hardwareInterface>hardware_interface/EffortJointInterface</hardwareInterface>
      <mechanicalReduction>1</mechanicalReduction>
    </actuator>
  </transmission>
  <transmission name="U2_tran">
    <type>transmission_interface/SimpleTransmission</type>
    <joint name="U2">
      <hardwareInterface>hardware_interface/EffortJointInterface</hardwareInterface>
    </joint>
    <actuator name="U2_actr">
      <hardwareInterface>hardware_interface/EffortJointInterface</hardwareInterface>
      <mechanicalReduction>1</mechanicalReduction>
    </actuator>
  </transmission>
  <transmission name="R2_tran">
    <type>transmission_interface/SimpleTransmission</type>
    <joint name="R2">
      <hardwareInterface>hardware_interface/EffortJointInterface</hardwareInterface>
    </joint>
    <actuator name="R2_actr">
      <hardwareInterface>hardware_interface/EffortJointInterface</hardwareInterface>
      <mechanicalReduction>1</mechanicalReduction>
    </actuator>
  </transmission>
  <transmission name="B2_tran">
    <type>transmission_interface/SimpleTransmission</type>
    <joint name="B2">
      <hardwareInterface>hardware_interface/EffortJointInterface</hardwareInterface>
    </joint>
    <actuator name="B2_actr">
      <hardwareInterface>hardware_interface/EffortJointInterface</hardwareInterface>
      <mechanicalReduction>1</mechanicalReduction>
    </actuator>
  </transmission>
  <transmission name="T2_tran">
    <type>transmission_interface/SimpleTransmission</type>
    <joint name="T2">
      <hardwareInterface>hardware_interface/EffortJointInterface</hardwareInterface>
    </joint>
    <actuator name="T2_actr">
      <hardwareInterface>hardware_interface/EffortJointInterface</hardwareInterface>
      <mechanicalReduction>1</mechanicalReduction>
    </actuator>
  </transmission>
  <transmission name="R1F1_tran">
    <type>transmission_interface/SimpleTransmission</type>
    <joint name="R1F1">
      <hardwareInterface>hardware_interface/EffortJointInterface</hardwareInterface>
    </joint>
    <actuator name="R1F1_actr">
      <hardwareInterface>hardware_interface/EffortJointInterface</hardwareInterface>
      <mechanicalReduction>1</mechanicalReduction>
    </actuator>
  </transmission>
  <transmission name="R1F2_tran">
    <type>transmission_interface/SimpleTransmission</type>
    <joint name="R1F2">
      <hardwareInterface>hardware_interface/EffortJointInterface</hardwareInterface>
    </joint>
    <actuator name="R1F2_actr">
      <hardwareInterface>hardware_interface/EffortJointInterface</hardwareInterface>
      <mechanicalReduction>1</mechanicalReduction>
    </actuator>
  </transmission>
  <transmission name="R2F1_tran">
    <type>transmission_interface/SimpleTransmission</type>
    <joint name="R2F1">
      <hardwareInterface>hardware_interface/EffortJointInterface</hardwareInterface>
    </joint>
    <actuator name="R2F1_actr">
      <hardwareInterface>hardware_interface/EffortJointInterface</hardwareInterface>
      <mechanicalReduction>1</mechanicalReduction>
    </actuator>
  </transmission>
  <transmission name="R2F2_tran">
    <type>transmission_interface/SimpleTransmission</type>
    <joint name="R2F2">
      <hardwareInterface>hardware_interface/EffortJointInterface</hardwareInterface>
    </joint>
    <actuator name="R2F2_actr">
      <hardwareInterface>hardware_interface/EffortJointInterface</hardwareInterface>
      <mechanicalReduction>1</mechanicalReduction>
    </actuator>
  </transmission>
  <gazebo>
    <plugin filename="libgazebo_ros_control.so" name="control"/>
  </gazebo>
  <gazebo reference="base_link">
    <material>Gazebo/Silver</material>
    <mu1>0.2</mu1>
    <mu2>0.2</mu2>
    <selfCollide>true</selfCollide>
    <gravity>true</gravity>
  </gazebo>
  <gazebo reference="SBASE_1">
    <material>Gazebo/Silver</material>
    <mu1>0.2</mu1>
    <mu2>0.2</mu2>
    <selfCollide>true</selfCollide>
  </gazebo>
  <gazebo reference="S1_1">
    <material>Gazebo/Silver</material>
    <mu1>0.2</mu1>
    <mu2>0.2</mu2>
    <selfCollide>true</selfCollide>
  </gazebo>
  <gazebo reference="L1_1">
    <material>Gazebo/Silver</material>
    <mu1>0.2</mu1>
    <mu2>0.2</mu2>
    <selfCollide>true</selfCollide>
  </gazebo>
  <gazebo reference="E1_1">
    <material>Gazebo/Silver</material>
    <mu1>0.2</mu1>
    <mu2>0.2</mu2>
    <selfCollide>true</selfCollide>
  </gazebo>
  <gazebo reference="U1_1">
    <material>Gazebo/Silver</material>
    <mu1>0.2</mu1>
    <mu2>0.2</mu2>
    <selfCollide>true</selfCollide>
  </gazebo>
  <gazebo reference="R1_1">
    <material>Gazebo/Silver</material>
    <mu1>0.2</mu1>
    <mu2>0.2</mu2>
    <selfCollide>true</selfCollide>
  </gazebo>
  <gazebo reference="B1_1">
    <material>Gazebo/Silver</material>
    <mu1>0.2</mu1>
    <mu2>0.2</mu2>
    <selfCollide>true</selfCollide>
  </gazebo>
  <gazebo reference="T1_1">
    <material>Gazebo/Silver</material>
    <mu1>0.2</mu1>
    <mu2>0.2</mu2>
    <selfCollide>true</selfCollide>
  </gazebo>
  <gazebo reference="S2_1">
    <material>Gazebo/Silver</material>
    <mu1>0.2</mu1>
    <mu2>0.2</mu2>
    <selfCollide>true</selfCollide>
  </gazebo>
  <gazebo reference="L2_1">
    <material>Gazebo/Silver</material>
    <mu1>0.2</mu1>
    <mu2>0.2</mu2>
    <selfCollide>true</selfCollide>
  </gazebo>
  <gazebo reference="E2_1">
    <material>Gazebo/Silver</material>
    <mu1>0.2</mu1>
    <mu2>0.2</mu2>
    <selfCollide>true</selfCollide>
  </gazebo>
  <gazebo reference="U2_1">
    <material>Gazebo/Silver</material>
    <mu1>0.2</mu1>
    <mu2>0.2</mu2>
    <selfCollide>true</selfCollide>
  </gazebo>
  <gazebo reference="R2_1">
    <material>Gazebo/Silver</material>
    <mu1>0.2</mu1>
    <mu2>0.2</mu2>
    <selfCollide>true</selfCollide>
  </gazebo>
  <gazebo reference="B2_1">
    <material>Gazebo/Silver</material>
    <mu1>0.2</mu1>
    <mu2>0.2</mu2>
    <selfCollide>true</selfCollide>
  </gazebo>
  <gazebo reference="T2_1">
    <material>Gazebo/Silver</material>
    <mu1>0.2</mu1>
    <mu2>0.2</mu2>
    <selfCollide>true</selfCollide>
  </gazebo>
  <gazebo reference="hand_1">
    <material>Gazebo/Silver</material>
    <mu1>0.2</mu1>
    <mu2>0.2</mu2>
    <selfCollide>true</selfCollide>
  </gazebo>
  <gazebo reference="hand__1__1">
    <material>Gazebo/Silver</material>
    <mu1>0.2</mu1>
    <mu2>0.2</mu2>
    <selfCollide>true</selfCollide>
  </gazebo>
  <gazebo reference="MAHOLO_FINGER_R__Simplified__v3_1">
    <material>Gazebo/Silver</material>
    <mu1>0.2</mu1>
    <mu2>0.2</mu2>
    <selfCollide>true</selfCollide>
  </gazebo>
  <gazebo reference="MAHOLO_FINGER_L__Simplified__v6_1">
    <material>Gazebo/Silver</material>
    <mu1>0.2</mu1>
    <mu2>0.2</mu2>
    <selfCollide>true</selfCollide>
  </gazebo>
  <gazebo reference="MAHOLO_FINGER_R__Simplified__v3__1__1">
    <material>Gazebo/Silver</material>
    <mu1>0.2</mu1>
    <mu2>0.2</mu2>
    <selfCollide>true</selfCollide>
  </gazebo>
  <gazebo reference="MAHOLO_FINGER_L__Simplified__v6__1__1">
    <material>Gazebo/Silver</material>
    <mu1>0.2</mu1>
    <mu2>0.2</mu2>
    <selfCollide>true</selfCollide>
  </gazebo>
  <link name="base_link">
    <inertial>
      <origin rpy="0 0 0" xyz="2.2433469729801996e-08 -0.05080457965626237 0.33381930788224"/>
      <mass value="181.30206575672864"/>
      <inertia ixx="13.450073" ixy="-0.0" ixz="1e-06" iyy="13.274199" iyz="1.404445" izz="2.922734"/>
    </inertial>
    <visual>
      <origin rpy="0 0 0" xyz="0 0 0"/>
      <geometry>
        <mesh filename="/root/csda10f/csda10f_precision_model_description/meshes/base_link.stl" scale="0.001 0.001 0.001"/>
      </geometry>
      <material name="silver"/>
    </visual>
    <collision>
      <origin rpy="0 0 0" xyz="0 0 0"/>
      <geometry>
        <mesh filename="/root/csda10f/csda10f_precision_model_description/meshes/base_link.stl" scale="0.001 0.001 0.001"/>
      </geometry>
    </collision>
  </link>
  <link name="SBASE_1">
    <inertial>
      <origin rpy="0 0 0" xyz="8.096157294561414e-09 -0.05522328590899421 0.2182019619316109"/>
      <mass value="60.457326411234085"/>
      <inertia ixx="1.176265" ixy="0.0" ixz="0.0" iyy="1.085087" iyz="0.275129" izz="0.630069"/>
    </inertial>
    <visual>
      <origin rpy="0 0 0" xyz="0.0 0.092509 -0.8935"/>
      <geometry>
        <mesh filename="/root/csda10f/csda10f_precision_model_description/meshes/SBASE_1.stl" scale="0.001 0.001 0.001"/>
      </geometry>
      <material name="silver"/>
    </visual>
    <collision>
      <origin rpy="0 0 0" xyz="0.0 0.092509 -0.8935"/>
      <geometry>
        <mesh filename="/root/csda10f/csda10f_precision_model_description/meshes/SBASE_1.stl" scale="0.001 0.001 0.001"/>
      </geometry>
    </collision>
  </link>
  <link name="S1_1">
    <inertial>
      <origin rpy="0 0 0" xyz="0.10958022689067523 0.020746595948014174 0.002601374363041753"/>
      <mass value="11.990565927774206"/>
      <inertia ixx="0.04229" ixy="-0.005344" ixz="-0.000672" iyy="0.067643" iyz="-8.3e-05" izz="0.068291"/>
    </inertial>
    <visual>
      <origin rpy="0 0 0" xyz="-0.123 0.192509 -1.2"/>
      <geometry>
        <mesh filename="/root/csda10f/csda10f_precision_model_description/meshes/S1_1.stl" scale="0.001 0.001 0.001"/>
      </geometry>
      <material name="silver"/>
    </visual>
    <collision>
      <origin rpy="0 0 0" xyz="-0.123 0.192509 -1.2"/>
      <geometry>
        <mesh filename="/root/csda10f/csda10f_precision_model_description/meshes/S1_1.stl" scale="0.001 0.001 0.001"/>
      </geometry>
    </collision>
  </link>
  <link name="L1_1">
    <inertial>
      <origin rpy="0 0 0" xyz="0.0024764405341893836 0.014067230579859952 -0.06622899736059429"/>
      <mass value="7.163278272082816"/>
      <inertia ixx="0.04823" ixy="-0.000603" ixz="0.000877" iyy="0.044685" iyz="0.015782" izz="0.026715"/>
    </inertial>
    <visual>
      <origin rpy="0 0 0" xyz="-0.265 0.237561 -1.194388"/>
      <geometry>
        <mesh filename="/root/csda10f/csda10f_precision_model_description/meshes/L1_1.stl" scale="0.001 0.001 0.001"/>
      </geometry>
      <material name="silver"/>
    </visual>
    <collision>
      <origin rpy="0 0 0" xyz="-0.265 0.237561 -1.194388"/>
      <geometry>
        <mesh filename="/root/csda10f/csda10f_precision_model_description/meshes/L1_1.stl" scale="0.001 0.001 0.001"/>
      </geometry>
    </collision>
  </link>
  <link name="E1_1">
    <inertial>
      <origin rpy="0 0 0" xyz="0.02563166397120198 0.016239483070428773 -0.11289951791422326"/>
      <mass value="6.994589067228431"/>
      <inertia ixx="0.044091" ixy="-0.000931" ixz="0.006796" iyy="0.044446" iyz="0.004322" izz="0.015181"/>
    </inertial>
    <visual>
      <origin rpy="0 0 0" xyz="-0.271413 0.170893 -1.026459"/>
      <geometry>
        <mesh filename="/root/csda10f/csda10f_precision_model_description/meshes/E1_1.stl" scale="0.001 0.001 0.001"/>
      </geometry>
      <material name="silver"/>
    </visual>
    <collision>
      <origin rpy="0 0 0" xyz="-0.271413 0.170893 -1.026459"/>
      <geometry>
        <mesh filename="/root/csda10f/csda10f_precision_model_description/meshes/E1_1.stl" scale="0.001 0.001 0.001"/>
      </geometry>
    </collision>
  </link>
  <link name="U1_1">
    <inertial>
      <origin rpy="0 0 0" xyz="-0.005285707583092103 -0.06554866067953771 0.04247939838914405"/>
      <mass value="5.11428801835745"/>
      <inertia ixx="0.029836" ixy="0.005805" ixz="-0.003932" iyy="0.016596" iyz="0.010061" izz="0.023857"/>
    </inertial>
    <visual>
      <origin rpy="0 0 0" xyz="-0.262779 0.1495 -0.842249"/>
      <geometry>
        <mesh filename="/root/csda10f/csda10f_precision_model_description/meshes/U1_1.stl" scale="0.001 0.001 0.001"/>
      </geometry>
      <material name="silver"/>
    </visual>
    <collision>
      <origin rpy="0 0 0" xyz="-0.262779 0.1495 -0.842249"/>
      <geometry>
        <mesh filename="/root/csda10f/csda10f_precision_model_description/meshes/U1_1.stl" scale="0.001 0.001 0.001"/>
      </geometry>
    </collision>
  </link>
  <link name="R1_1">
    <inertial>
      <origin rpy="0 0 0" xyz="-0.012106225254944258 -0.08699872198053743 0.05721125758696455"/>
      <mass value="4.526669338517219"/>
      <inertia ixx="0.022423" ixy="-0.001911" ixz="0.001249" iyy="0.01133" iyz="0.007529" izz="0.017871"/>
    </inertial>
    <visual>
      <origin rpy="0 0 0" xyz="-0.288139 0.308088 -0.949503"/>
      <geometry>
        <mesh filename="/root/csda10f/csda10f_precision_model_description/meshes/R1_1.stl" scale="0.001 0.001 0.001"/>
      </geometry>
      <material name="silver"/>
    </visual>
    <collision>
      <origin rpy="0 0 0" xyz="-0.288139 0.308088 -0.949503"/>
      <geometry>
        <mesh filename="/root/csda10f/csda10f_precision_model_description/meshes/R1_1.stl" scale="0.001 0.001 0.001"/>
      </geometry>
    </collision>
  </link>
  <link name="B1_1">
    <inertial>
      <origin rpy="0 0 0" xyz="0.004283949653296426 0.0003122402239437161 0.04774324430963883"/>
      <mass value="2.95336548278132"/>
      <inertia ixx="0.008702" ixy="-1e-05" ixz="0.002243" iyy="0.008907" iyz="0.000129" izz="0.004722"/>
    </inertial>
    <visual>
      <origin rpy="0 0 0" xyz="-0.311767 0.446441 -1.042138"/>
      <geometry>
        <mesh filename="/root/csda10f/csda10f_precision_model_description/meshes/B1_1.stl" scale="0.001 0.001 0.001"/>
      </geometry>
      <material name="silver"/>
    </visual>
    <collision>
      <origin rpy="0 0 0" xyz="-0.311767 0.446441 -1.042138"/>
      <geometry>
        <mesh filename="/root/csda10f/csda10f_precision_model_description/meshes/B1_1.stl" scale="0.001 0.001 0.001"/>
      </geometry>
    </collision>
  </link>
  <link name="T1_1">
    <inertial>
      <origin rpy="0 0 0" xyz="5.513778420174198e-05 0.00014597386289000314 0.02481872183091305"/>
      <mass value="1.32607221578546"/>
      <inertia ixx="0.001271" ixy="0.0" ixz="1e-06" iyy="0.001289" iyz="3e-06" izz="0.001933"/>
    </inertial>
    <visual>
      <origin rpy="0 0 0" xyz="-0.297053 0.446938 -1.160173"/>
      <geometry>
        <mesh filename="/root/csda10f/csda10f_precision_model_description/meshes/T1_1.stl" scale="0.001 0.001 0.001"/>
      </geometry>
      <material name="silver"/>
    </visual>
    <collision>
      <origin rpy="0 0 0" xyz="-0.297053 0.446938 -1.160173"/>
      <geometry>
        <mesh filename="/root/csda10f/csda10f_precision_model_description/meshes/T1_1.stl" scale="0.001 0.001 0.001"/>
      </geometry>
    </collision>
  </link>
  <link name="S2_1">
    <inertial>
      <origin rpy="0 0 0" xyz="-0.10958022828177219 0.020750832945751807 0.0025673577130338465"/>
      <mass value="11.990565927774206"/>
      <inertia ixx="0.04229" ixy="0.005346" ixz="0.00066" iyy="0.067642" iyz="-8.1e-05" izz="0.068291"/>
    </inertial>
    <visual>
      <origin rpy="0 0 0" xyz="0.123 0.192509 -1.2"/>
      <geometry>
        <mesh filename="/root/csda10f/csda10f_precision_model_description/meshes/S2_1.stl" scale="0.001 0.001 0.001"/>
      </geometry>
      <material name="silver"/>
    </visual>
    <collision>
      <origin rpy="0 0 0" xyz="0.123 0.192509 -1.2"/>
      <geometry>
        <mesh filename="/root/csda10f/csda10f_precision_model_description/meshes/S2_1.stl" scale="0.001 0.001 0.001"/>
      </geometry>
    </collision>
  </link>
  <link name="L2_1">
    <inertial>
      <origin rpy="0 0 0" xyz="-0.002470882958283682 0.014067255774551868 -0.0662291996356148"/>
      <mass value="7.163278272082816"/>
      <inertia ixx="0.048233" ixy="0.000578" ixz="-0.000835" iyy="0.044685" iyz="0.015783" izz="0.026712"/>
    </inertial>
    <visual>
      <origin rpy="0 0 0" xyz="0.265 0.237561 -1.194388"/>
      <geometry>
        <mesh filename="/root/csda10f/csda10f_precision_model_description/meshes/L2_1.stl" scale="0.001 0.001 0.001"/>
      </geometry>
      <material name="silver"/>
    </visual>
    <collision>
      <origin rpy="0 0 0" xyz="0.265 0.237561 -1.194388"/>
      <geometry>
        <mesh filename="/root/csda10f/csda10f_precision_model_description/meshes/L2_1.stl" scale="0.001 0.001 0.001"/>
      </geometry>
    </collision>
  </link>
  <link name="E2_1">
    <inertial>
      <origin rpy="0 0 0" xyz="-0.02563580558053885 0.016198275073866203 -0.11290449765348587"/>
      <mass value="6.994589067228431"/>
      <inertia ixx="0.044087" ixy="0.000909" ixz="-0.006804" iyy="0.044463" iyz="0.004269" izz="0.015168"/>
    </inertial>
    <visual>
      <origin rpy="0 0 0" xyz="0.271413 0.170893 -1.026459"/>
      <geometry>
        <mesh filename="/root/csda10f/csda10f_precision_model_description/meshes/E2_1.stl" scale="0.001 0.001 0.001"/>
      </geometry>
      <material name="silver"/>
    </visual>
    <collision>
      <origin rpy="0 0 0" xyz="0.271413 0.170893 -1.026459"/>
      <geometry>
        <mesh filename="/root/csda10f/csda10f_precision_model_description/meshes/E2_1.stl" scale="0.001 0.001 0.001"/>
      </geometry>
    </collision>
  </link>
  <link name="U2_1">
    <inertial>
      <origin rpy="0 0 0" xyz="0.005303516463993518 -0.0654430130876767 0.04263982289479462"/>
      <mass value="5.11428801835745"/>
      <inertia ixx="0.029839" ixy="-0.005794" ixz="0.003944" iyy="0.016615" iyz="0.010069" izz="0.023835"/>
    </inertial>
    <visual>
      <origin rpy="0 0 0" xyz="0.262779 0.1495 -0.842249"/>
      <geometry>
        <mesh filename="/root/csda10f/csda10f_precision_model_description/meshes/U2_1.stl" scale="0.001 0.001 0.001"/>
      </geometry>
      <material name="silver"/>
    </visual>
    <collision>
      <origin rpy="0 0 0" xyz="0.262779 0.1495 -0.842249"/>
      <geometry>
        <mesh filename="/root/csda10f/csda10f_precision_model_description/meshes/U2_1.stl" scale="0.001 0.001 0.001"/>
      </geometry>
    </collision>
  </link>
  <link name="R2_1">
    <inertial>
      <origin rpy="0 0 0" xyz="0.012107586495043843 -0.08698001123805554 0.057240727448463535"/>
      <mass value="4.526669338517219"/>
      <inertia ixx="0.022423" ixy="0.001909" ixz="-0.001254" iyy="0.01135" iyz="0.007538" izz="0.017852"/>
    </inertial>
    <visual>
      <origin rpy="0 0 0" xyz="0.288137 0.308074 -0.949523"/>
      <geometry>
        <mesh filename="/root/csda10f/csda10f_precision_model_description/meshes/R2_1.stl" scale="0.001 0.001 0.001"/>
      </geometry>
      <material name="silver"/>
    </visual>
    <collision>
      <origin rpy="0 0 0" xyz="0.288137 0.308074 -0.949523"/>
      <geometry>
        <mesh filename="/root/csda10f/csda10f_precision_model_description/meshes/R2_1.stl" scale="0.001 0.001 0.001"/>
      </geometry>
    </collision>
  </link>
  <link name="B2_1">
    <inertial>
      <origin rpy="0 0 0" xyz="-0.004270859650056247 0.0005244614670172898 0.04774294326565798"/>
      <mass value="2.95336548278132"/>
      <inertia ixx="0.008701" ixy="-0.0" ixz="-0.002244" iyy="0.008908" iyz="0.000115" izz="0.004722"/>
    </inertial>
    <visual>
      <origin rpy="0 0 0" xyz="0.311765 0.446428 -1.042158"/>
      <geometry>
        <mesh filename="/root/csda10f/csda10f_precision_model_description/meshes/B2_1.stl" scale="0.001 0.001 0.001"/>
      </geometry>
      <material name="silver"/>
    </visual>
    <collision>
      <origin rpy="0 0 0" xyz="0.311765 0.446428 -1.042158"/>
      <geometry>
        <mesh filename="/root/csda10f/csda10f_precision_model_description/meshes/B2_1.stl" scale="0.001 0.001 0.001"/>
      </geometry>
    </collision>
  </link>
  <link name="T2_1">
    <inertial>
      <origin rpy="0 0 0" xyz="-5.487369243661888e-05 0.00014641235658008345 0.024819128010264313"/>
      <mass value="1.32607221578546"/>
      <inertia ixx="0.001271" ixy="-0.0" ixz="-1e-06" iyy="0.001289" iyz="3e-06" izz="0.001933"/>
    </inertial>
    <visual>
      <origin rpy="0 0 0" xyz="0.297051 0.446925 -1.160193"/>
      <geometry>
        <mesh filename="/root/csda10f/csda10f_precision_model_description/meshes/T2_1.stl" scale="0.001 0.001 0.001"/>
      </geometry>
      <material name="silver"/>
    </visual>
    <collision>
      <origin rpy="0 0 0" xyz="0.297051 0.446925 -1.160193"/>
      <geometry>
        <mesh filename="/root/csda10f/csda10f_precision_model_description/meshes/T2_1.stl" scale="0.001 0.001 0.001"/>
      </geometry>
    </collision>
  </link>
  <link name="hand_1">
    <inertial>
      <origin rpy="0 0 0" xyz="-0.0015522933470878408 0.0006434450999144858 0.031105904550830843"/>
      <mass value="2.4978751024280967"/>
      <inertia ixx="0.00328" ixy="4e-06" ixz="0.000102" iyy="0.00502" iyz="-0.000282" izz="0.003921"/>
    </inertial>
    <visual>
      <origin rpy="0 0 0" xyz="0.297176 0.446727 -1.217193"/>
      <geometry>
        <mesh filename="/root/csda10f/csda10f_precision_model_description/meshes/hand_1.stl" scale="0.001 0.001 0.001"/>
      </geometry>
      <material name="silver"/>
    </visual>
    <collision>
      <origin rpy="0 0 0" xyz="0.297176 0.446727 -1.217193"/>
      <geometry>
        <mesh filename="/root/csda10f/csda10f_precision_model_description/meshes/hand_1.stl" scale="0.001 0.001 0.001"/>
      </geometry>
    </collision>
  </link>
  <link name="hand__1__1">
    <inertial>
      <origin rpy="0 0 0" xyz="-0.001408545353336954 0.0006610041949101642 0.03131293250758094"/>
      <mass value="2.4978751024280967"/>
      <inertia ixx="0.003281" ixy="2.3e-05" ixz="0.000101" iyy="0.00502" iyz="-0.000283" izz="0.00392"/>
    </inertial>
    <visual>
      <origin rpy="0 0 0" xyz="-0.297178 0.44674 -1.217172"/>
      <geometry>
        <mesh filename="/root/csda10f/csda10f_precision_model_description/meshes/hand__1__1.stl" scale="0.001 0.001 0.001"/>
      </geometry>
      <material name="silver"/>
    </visual>
    <collision>
      <origin rpy="0 0 0" xyz="-0.297178 0.44674 -1.217172"/>
      <geometry>
        <mesh filename="/root/csda10f/csda10f_precision_model_description/meshes/hand__1__1.stl" scale="0.001 0.001 0.001"/>
      </geometry>
    </collision>
  </link>
  <link name="MAHOLO_FINGER_R__Simplified__v3_1">
    <inertial>
      <origin rpy="0 0 0" xyz="-0.05334915960283948 0.01438645514534792 0.02643242837160753"/>
      <mass value="0.3929891910645346"/>
      <inertia ixx="0.000399" ixy="-0.0" ixz="1e-05" iyy="0.000341" iyz="0.000107" izz="0.00014"/>
    </inertial>
    <visual>
      <origin rpy="0 0 0" xyz="0.26053 0.450693 -1.309187"/>
      <geometry>
        <mesh filename="/root/csda10f/csda10f_precision_model_description/meshes/MAHOLO_FINGER_R__Simplified__v3_1.stl" scale="0.001 0.001 0.001"/>
      </geometry>
      <material name="silver"/>
    </visual>
    <collision>
      <origin rpy="0 0 0" xyz="0.26053 0.450693 -1.309187"/>
      <geometry>
        <mesh filename="/root/csda10f/csda10f_precision_model_description/meshes/MAHOLO_FINGER_R__Simplified__v3_1.stl" scale="0.001 0.001 0.001"/>
      </geometry>
    </collision>
  </link>
  <link name="MAHOLO_FINGER_L__Simplified__v6_1">
    <inertial>
      <origin rpy="0 0 0" xyz="0.053148434594437244 0.006160799630561098 0.026694362446108233"/>
      <mass value="0.39298919106453456"/>
      <inertia ixx="0.000397" ixy="3e-06" ixz="-9e-06" iyy="0.000341" iyz="0.000109" izz="0.000138"/>
    </inertial>
    <visual>
      <origin rpy="0 0 0" xyz="0.334143 0.442123 -1.308996"/>
      <geometry>
        <mesh filename="/root/csda10f/csda10f_precision_model_description/meshes/MAHOLO_FINGER_L__Simplified__v6_1.stl" scale="0.001 0.001 0.001"/>
      </geometry>
      <material name="silver"/>
    </visual>
    <collision>
      <origin rpy="0 0 0" xyz="0.334143 0.442123 -1.308996"/>
      <geometry>
        <mesh filename="/root/csda10f/csda10f_precision_model_description/meshes/MAHOLO_FINGER_L__Simplified__v6_1.stl" scale="0.001 0.001 0.001"/>
      </geometry>
    </collision>
  </link>
  <link name="MAHOLO_FINGER_R__Simplified__v3__1__1">
    <inertial>
      <origin rpy="0 0 0" xyz="-0.053062488533561436 0.015008163994905455 0.026663230482674605"/>
      <mass value="0.3929891910645346"/>
      <inertia ixx="0.000399" ixy="-0.0" ixz="1e-05" iyy="0.000341" iyz="0.000106" izz="0.00014"/>
    </inertial>
    <visual>
      <origin rpy="0 0 0" xyz="-0.334176 0.451136 -1.309207"/>
      <geometry>
        <mesh filename="/root/csda10f/csda10f_precision_model_description/meshes/MAHOLO_FINGER_R__Simplified__v3__1__1.stl" scale="0.001 0.001 0.001"/>
      </geometry>
      <material name="silver"/>
    </visual>
    <collision>
      <origin rpy="0 0 0" xyz="-0.334176 0.451136 -1.309207"/>
      <geometry>
        <mesh filename="/root/csda10f/csda10f_precision_model_description/meshes/MAHOLO_FINGER_R__Simplified__v3__1__1.stl" scale="0.001 0.001 0.001"/>
      </geometry>
    </collision>
  </link>
  <link name="MAHOLO_FINGER_L__Simplified__v6__1__1">
    <inertial>
      <origin rpy="0 0 0" xyz="0.053331881935138215 0.005538233961328964 0.026462235518623034"/>
      <mass value="0.39298919106453456"/>
      <inertia ixx="0.000397" ixy="3e-06" ixz="-9e-06" iyy="0.000341" iyz="0.00011" izz="0.000138"/>
    </inertial>
    <visual>
      <origin rpy="0 0 0" xyz="-0.260668 0.441706 -1.309336"/>
      <geometry>
        <mesh filename="/root/csda10f/csda10f_precision_model_description/meshes/MAHOLO_FINGER_L__Simplified__v6__1__1.stl" scale="0.001 0.001 0.001"/>
      </geometry>
      <material name="silver"/>
    </visual>
    <collision>
      <origin rpy="0 0 0" xyz="-0.260668 0.441706 -1.309336"/>
      <geometry>
        <mesh filename="/root/csda10f/csda10f_precision_model_description/meshes/MAHOLO_FINGER_L__Simplified__v6__1__1.stl" scale="0.001 0.001 0.001"/>
      </geometry>
    </collision>
  </link>
  <joint name="A1" type="revolute">
    <origin rpy="0 0 0" xyz="0.0 -0.092509 0.8935"/>
    <parent link="base_link"/>
    <child link="SBASE_1"/>
    <axis xyz="0.0 -0.0 -1.0"/>
    <limit effort="100" lower="-2.96706" upper="2.96706" velocity="100"/>
  </joint>
  <joint name="S1" type="revolute">
    <origin rpy="0 0 0" xyz="0.123 -0.1 0.3065"/>
    <parent link="SBASE_1"/>
    <child link="S1_1"/>
    <axis xyz="-1.0 0.0 0.0"/>
    <limit effort="100" lower="-3.141593" upper="3.141593" velocity="100"/>
  </joint>
  <joint name="L1" type="revolute">
    <origin rpy="0 0 0" xyz="0.142 -0.045052 -0.005612"/>
    <parent link="S1_1"/>
    <child link="L1_1"/>
    <axis xyz="0.0 -0.992332 -0.123601"/>
    <limit effort="100" lower="-1.919862" upper="1.919862" velocity="100"/>
  </joint>
  <joint name="E1" type="revolute">
    <origin rpy="0 0 0" xyz="0.006413 0.066668 -0.167929"/>
    <parent link="L1_1"/>
    <child link="E1_1"/>
    <axis xyz="0.036644 0.123518 -0.991665"/>
    <limit effort="100" lower="-2.96706" upper="2.96706" velocity="100"/>
  </joint>
  <joint name="U1" type="revolute">
    <origin rpy="0 0 0" xyz="-0.008634 0.021393 -0.18421"/>
    <parent link="E1_1"/>
    <child link="U1_1"/>
    <axis xyz="-0.994387 -0.094051 -0.048459"/>
    <limit effort="100" lower="-2.356194" upper="2.356194" velocity="100"/>
  </joint>
  <joint name="R1" type="revolute">
    <origin rpy="0 0 0" xyz="0.02536 -0.158588 0.107254"/>
    <parent link="U1_1"/>
    <child link="R1_1"/>
    <axis xyz="0.051674 -0.831405 0.553259"/>
    <limit effort="100" lower="-3.141593" upper="3.141593" velocity="100"/>
  </joint>
  <joint name="B1" type="revolute">
    <origin rpy="0 0 0" xyz="0.023628 -0.138353 0.092635"/>
    <parent link="R1_1"/>
    <child link="B1_1"/>
    <axis xyz="0.998169 0.060443 -0.002399"/>
    <limit effort="100" lower="-1.919862" upper="1.919862" velocity="100"/>
  </joint>
  <joint name="T1" type="revolute">
    <origin rpy="0 0 0" xyz="-0.014714 -0.000497 0.118035"/>
    <parent link="B1_1"/>
    <child link="T1_1"/>
    <axis xyz="0.002193 0.003472 0.999992"/>
    <limit effort="100" lower="-3.141593" upper="3.141593" velocity="100"/>
  </joint>
  <joint name="S2" type="revolute">
    <origin rpy="0 0 0" xyz="-0.123 -0.1 0.3065"/>
    <parent link="SBASE_1"/>
    <child link="S2_1"/>
    <axis xyz="1.0 -0.0 0.0"/>
    <limit effort="100" lower="-3.141593" upper="3.141593" velocity="100"/>
  </joint>
  <joint name="L2" type="revolute">
    <origin rpy="0 0 0" xyz="-0.142 -0.045052 -0.005612"/>
    <parent link="S2_1"/>
    <child link="L2_1"/>
    <axis xyz="-0.0 -0.992332 -0.123601"/>
    <limit effort="100" lower="-1.919862" upper="1.919862" velocity="100"/>
  </joint>
  <joint name="E2" type="revolute">
    <origin rpy="0 0 0" xyz="-0.006413 0.066668 -0.167929"/>
    <parent link="L2_1"/>
    <child link="E2_1"/>
    <axis xyz="-0.036644 0.123518 -0.991665"/>
    <limit effort="100" lower="-2.96706" upper="2.96706" velocity="100"/>
  </joint>
  <joint name="U2" type="revolute">
    <origin rpy="0 0 0" xyz="0.008634 0.021393 -0.18421"/>
    <parent link="E2_1"/>
    <child link="U2_1"/>
    <axis xyz="0.994387 -0.094051 -0.048459"/>
    <limit effort="100" lower="-2.356194" upper="2.356194" velocity="100"/>
  </joint>
  <joint name="R2" type="revolute">
    <origin rpy="0 0 0" xyz="-0.025358 -0.158574 0.107274"/>
    <parent link="U2_1"/>
    <child link="R2_1"/>
    <axis xyz="-0.051674 -0.831405 0.553259"/>
    <limit effort="100" lower="-3.141593" upper="3.141593" velocity="100"/>
  </joint>
  <joint name="B2" type="revolute">
    <origin rpy="0 0 0" xyz="-0.023628 -0.138354 0.092635"/>
    <parent link="R2_1"/>
    <child link="B2_1"/>
    <axis xyz="-0.998169 0.060443 -0.002399"/>
    <limit effort="100" lower="-1.919862" upper="1.919862" velocity="100"/>
  </joint>
  <joint name="T2" type="continuous">
    <origin rpy="0 0 0" xyz="0.014714 -0.000497 0.118035"/>
    <parent link="B2_1"/>
    <child link="T2_1"/>
    <axis xyz="-0.002193 0.003472 0.999992"/>
  </joint>
  <joint name="FixR1" type="fixed">
    <origin rpy="0 0 0" xyz="-0.000125 0.000198 0.057"/>
    <parent link="T2_1"/>
    <child link="hand_1"/>
  </joint>
  <joint name="FixR2" type="fixed">
    <origin rpy="0 0 0" xyz="0.000125 0.000198 0.056999"/>
    <parent link="T1_1"/>
    <child link="hand__1__1"/>
  </joint>
  <joint name="R1F1" type="prismatic">
    <origin rpy="0 0 0" xyz="0.036646 -0.003966 0.091994"/>
    <parent link="hand_1"/>
    <child link="MAHOLO_FINGER_R__Simplified__v3_1"/>
    <axis xyz="0.999981 0.005843 0.002173"/>
    <limit effort="100" lower="-0.024" upper="0.0" velocity="100"/>
  </joint>
  <joint name="R1F2" type="prismatic">
    <origin rpy="0 0 0" xyz="-0.036967 0.004604 0.091803"/>
    <parent link="hand_1"/>
    <child link="MAHOLO_FINGER_L__Simplified__v6_1"/>
    <axis xyz="-0.999981 -0.005843 -0.002173"/>
    <limit effort="100" lower="-0.024" upper="0.0" velocity="100"/>
  </joint>
  <joint name="R2F1" type="prismatic">
    <origin rpy="0 0 0" xyz="0.036998 -0.004396 0.092035"/>
    <parent link="hand__1__1"/>
    <child link="MAHOLO_FINGER_R__Simplified__v3__1__1"/>
    <axis xyz="0.999981 -0.005843 -0.002173"/>
    <limit effort="100" lower="-0.024" upper="0.0" velocity="100"/>
  </joint>
  <joint name="R2F2" type="prismatic">
    <origin rpy="0 0 0" xyz="-0.03651 0.005034 0.092164"/>
    <parent link="hand__1__1"/>
    <child link="MAHOLO_FINGER_L__Simplified__v6__1__1"/>
    <axis xyz="-0.999981 0.005843 0.002173"/>
    <limit effort="100" lower="-0.024" upper="0.0" velocity="100"/>
  </joint>
</robot>
